<mujoco model="vx300s">
  <compiler angle="radian" meshdir="meshes/"/>


  <option integrator="implicitfast"/>

  <default>
    <default class="vx300s">
      <default class="visual">
        <geom type="mesh" contype="0" conaffinity="0" group="2"/>
      </default>
      <default class="collision">
        <geom type="capsule" group="3"/>
        <default class="eef_collision">
          <geom type="cylinder"/>
        </default>
      </default>
      <joint axis="0 1 0" range="-6.28319 6.28319"/>
      <default class="joint_limited">
        <joint range="-3.1415 3.1415"/>
      </default>
      <default class="position">
        <position ctrlrange="-6.2831 6.2831" kp="2000" kv="100" forcerange="-50 50"/>
        <default class="position_limited">
          <position ctrlrange="-3.1415 3.1415"/>
        </default>
        <default class="position_small">
          <position kp="500" kv="50" forcerange="-28 28"/>
        </default>
      </default>
    </default>
  </default>

  <asset>
    <mesh name="base" file="base.stl" scale="0.001 0.001 0.001"/>
    <mesh name="shoulder" file="shoulder.stl" scale="0.001 0.001 0.001"/>
    <mesh name="upper_arm" file="upper_arm.stl" scale="0.001 0.001 0.001"/>
    <mesh name="upper_forearm" file="upper_forearm.stl" scale="0.001 0.001 0.001"/>
    <mesh name="lower_forearm" file="lower_forearm.stl" scale="0.001 0.001 0.001"/>
    <mesh name="wrist" file="wrist.stl" scale="0.001 0.001 0.001"/>
    <mesh name="gripper" file="gripper.stl" scale="0.001 0.001 0.001"/>
    <mesh name="gripper_prop" file="gripper_prop.stl" scale="0.001 0.001 0.001"/>
    <mesh name="gripper_bar" file="gripper_bar.stl" scale="0.001 0.001 0.001"/>
    <mesh name="gripper_finger" file="gripper_finger.stl" scale="0.001 0.001 0.001"/>
  </asset>

  <worldbody>
    <body name="vx300s/base_link" pos="0 0 0.079">
      <inertial pos="0.000259233 -3.3552e-06 0.0116129" quat="0.0330273 0.706309 0.033027 0.706361" mass="0.798614" diaginertia="0.00120156 0.00113744 0.0009388"/>
      <geom pos="0 0 -0.003" quat="0.707107 0 0 0.707107" type="mesh" contype="0" conaffinity="0" group="1" density="0" mesh="base"/>
      <geom pos="0 0 -0.003" quat="0.707107 0 0 0.707107" type="mesh" mesh="base"/>
      <!-- <geom quat="0.707107 0 0 0.707107" type="mesh" contype="0" conaffinity="0" group="1" density="0" mesh="base"/>
      <geom quat="0.707107 0 0 0.707107" type="mesh" mesh="base"/> -->
    <body name="vx300s/shoulder_link" pos="0 0 0.079">
      <inertial pos="0.000259233 -3.3552e-06 0.0116129" quat="0.0330273 0.706309 0.033027 0.706361" mass="0.798614" diaginertia="0.00120156 0.00113744 0.0009388"/>
      <joint name="waist" pos="0 0 0" axis="0 0 1" range="-3.14158 3.14158" actuatorfrcrange="-10 10" damping="0.1" frictionloss="0.1"/>
      <geom pos="0 0 -0.003" quat="0.707107 0 0 0.707107" type="mesh" contype="0" conaffinity="0" group="1" density="0" mesh="shoulder"/>
      <geom pos="0 0 -0.003" quat="0.707107 0 0 0.707107" type="mesh" mesh="shoulder"/>
      <body name="vx300s/upper_arm_link" pos="0 0 0.04805">
        <inertial pos="0.0206949 4e-10 0.226459" quat="0.705228 0.0515097 -0.0515097 0.705228" mass="0.792592" diaginertia="0.00911338 0.008925 0.000759317"/>
        <joint name="shoulder" pos="0 0 0" axis="0 1 0" range="-1.85005 1.25664" actuatorfrcrange="-20 20" damping="0.1" frictionloss="0.1"/>
        <geom pos="0 0 0" quat="0.707107 0 0 0.707107" type="mesh" contype="0" conaffinity="0" group="1" density="0" mesh="upper_arm"/>
        <geom pos="0 0 0" quat="0.707107 0 0 0.707107" type="mesh" mesh="upper_arm"/>
        <body name="vx300s/upper_forearm_link" pos="0.05955 0 0.3">
          <inertial pos="0.105723 0 0" quat="-0.000621631 0.704724 0.0105292 0.709403" mass="0.322228" diaginertia="0.00144107 0.00134228 0.000152047"/>
          <joint name="elbow" pos="0 0 0" axis="0 1 0" range="-1.76278 1.6057" actuatorfrcrange="-15 15" damping="0.1" frictionloss="0.1"/>
          <geom type="mesh" contype="0" conaffinity="0" group="1" density="0" mesh="upper_forearm"/>
          <geom type="mesh" mesh="upper_forearm"/>
          <body name="vx300s/lower_forearm_link" pos="0.2 0 0">
            <inertial pos="0.0513477 0.00680462 0" quat="-0.0796724 0.702604 0.0796724 0.702604" mass="0.414823" diaginertia="0.0005911 0.000546493 0.000155707"/>
            <joint name="forearm_roll" pos="0 0 0" axis="1 0 0" range="-3.14158 3.14158" actuatorfrcrange="-2 2" damping="0.1" frictionloss="0.1"/>
            <geom pos="0 0 0" quat="0 1 0 0" type="mesh" contype="0" conaffinity="0" group="1" density="0" mesh="lower_forearm"/>
            <geom pos="0 0 0" quat="0 1 0 0" type="mesh" mesh="lower_forearm"/>
            <body name="vx300s/wrist_link" pos="0.1 0 0">
              <inertial pos="0.046743 -7.6652e-06 0.010565" quat="0.592342 0.38696 -0.383201 0.593759" mass="0.115395" diaginertia="5.45707e-05 4.63101e-05 4.32692e-05"/>
              <joint name="wrist_angle" pos="0 0 0" axis="0 1 0" range="-1.8675 2.23402" actuatorfrcrange="-5 5" damping="0.1" frictionloss="0.1"/>
              <geom pos="0 0 0" quat="0.707107 0 0 0.707107" type="mesh" contype="0" conaffinity="0" group="1" density="0" mesh="wrist"/>
              <geom pos="0 0 0" quat="0.707107 0 0 0.707107" type="mesh" mesh="wrist"/>
              <body name="vx300s/gripper_link" pos="0.069744 0 0">
                <inertial pos="0.0395662 -2.56311e-07 0.00400649" quat="0.463635 0.536087 0.50101 0.496631" mass="0.251652" diaginertia="0.00070931 0.000679582 0.000419112"/>
                <joint name="wrist_rotate" pos="0 0 0" axis="1 0 0" range="-3.14158 3.14158" actuatorfrcrange="-1 1" damping="0.1" frictionloss="0.1"/>
                <geom pos="-0.02 0 0" quat="0.707107 0 0 0.707107" type="mesh" contype="0" conaffinity="0" group="1" density="0" mesh="gripper"/>
                <geom pos="-0.02 0 0" quat="0.707107 0 0 0.707107" type="mesh" mesh="gripper"/>
                <geom pos="-0.020175 0 0" quat="0.707107 0 0 0.707107" type="mesh" contype="0" conaffinity="0" group="1" density="0" mesh="gripper_bar"/>
                <geom pos="-0.020175 0 0" quat="0.707107 0 0 0.707107" type="mesh" mesh="gripper_bar"/>
                <body name="vx300s/gripper_prop_link" pos="0.0485 0 0">
                  <inertial pos="0.002378 2.85e-08 0" quat="0.311559 0.634769 0.634769 0.311559" mass="0.008009" diaginertia="4.2979e-06 2.8868e-06 1.5314e-06"/>
                  <joint name="gripper" pos="0 0 0" axis="1 0 0" actuatorfrcrange="-1 1" damping="0.1" frictionloss="0.1"/>
                  <geom pos="-0.0685 0 0" quat="0.707107 0 0 0.707107" type="mesh" contype="0" conaffinity="0" group="1" density="0" mesh="gripper_prop"/>
                  <geom pos="-0.0685 0 0" quat="0.707107 0 0 0.707107" type="mesh" mesh="gripper_prop"/>
                </body>
                <body name="vx300s/left_finger_link" pos="0.0687 0 0">
                  <inertial pos="0.017344 -0.0060692 0" quat="0.7038 0.7038 -0.0683038 -0.0683038" mass="0.034796" diaginertia="2.48003e-05 1.417e-05 1.20797e-05"/>
                  <joint name="left_finger" pos="0 0 0" axis="0 1 0" type="slide" range="0.021 0.057" actuatorfrcrange="-5 5" damping="0.1" frictionloss="0.1"/>
                  <geom pos="-0.0404 -0.0575 0" quat="-0.5 0.5 -0.5 0.5" type="mesh" contype="0" conaffinity="0" group="1" density="0" mesh="gripper_finger"/>
                  <geom pos="-0.0404 -0.0575 0" quat="-0.5 0.5 -0.5 0.5" type="mesh" mesh="gripper_finger"/>
                </body>
                <body name="vx300s/right_finger_link" pos="0.0687 0 0">
                  <inertial pos="0.017344 0.0060692 0" quat="0.703801 0.703801 0.0682961 0.0682961" mass="0.034796" diaginertia="2.48002e-05 1.417e-05 1.20798e-05"/>
                  <joint name="right_finger" pos="0 0 0" axis="0 1 0" type="slide" range="-0.057 -0.021" actuatorfrcrange="-5 5" damping="0.1" frictionloss="0.1"/>
                  <geom pos="-0.0404 0.0575 0" quat="0.5 0.5 0.5 0.5" type="mesh" contype="0" conaffinity="0" group="1" density="0" mesh="gripper_finger"/>
                  <geom pos="-0.0404 0.0575 0" quat="0.5 0.5 0.5 0.5" type="mesh" mesh="gripper_finger"/>
                </body>
              </body>
            </body>
          </body>
        </body>
      </body>
    </body>
    </body>
  </worldbody>


  <actuator>
    <position class="position" name="waist" joint="waist"/>
    <position class="position" name="shoulder" joint="shoulder"/>
    <position class="position_limited" name="elbow" joint="elbow"/>
    <position class="position_small" name="forearm_roll" joint="forearm_roll"/>
    <position class="position_limited" name="wrist_angle" joint="wrist_angle"/>
    <position class="position_limited" name="wrist_rotate" joint="wrist_rotate"/>
    <position class="position_small" name="gripper" joint="gripper"/>
  </actuator>

  <keyframe>
    <key name="home" qpos="0 0 0 0 0 0 0 0 0" ctrl="0 0 0 0 0 0 0"/>
  </keyframe>


</mujoco>
